Workbook

Sheet SUMMARY
A1: SEEMA SAREE CENTRE | G1: TYPE | H1: AMOUNT
A2: SHREE GANPATI LOGISTIC AND TRANSPORT | G2: LOOSE | H2: 800
A3: SUMMARY (2026-2027) | G3: BOX | H3: 1050
A4: MONTHS | B4: TOTAL PARCEL | C4: LOOSE | D4: BOX | E4: DIFFERENCE | F4: LOOSE AMOUNT | G4: BOX AMOUNT | H4: TOTAL AMOUNT
A6: JUNE | B6: =SUM('JUNE 2026'!$H$1:$H$1000) -> 193 | C6: =COUNTIF('JUNE 2026'!$G$1:$G$1000, "L") -> 191 | D6: =COUNTIF('JUNE 2026'!$G$1:$G$1000, "B") -> 2 | E6: =B6-(C6+D6) -> 0 | F6: =$C6*$H$2 -> 152800 | G6: =$D6*$H$3 -> 2100 | H6: =SUM($F6,$G6) -> 154900
A7: JULY | B7: =SUM('JULY 2026'!$H$1:$H$1000) -> 34 | C7: =COUNTIF('JULY 2026'!$G$1:$G$1000, "L") -> 33 | D7: =COUNTIF('JULY 2026'!$G$1:$G$1000, "B") -> 1 | E7: =B7-(C7+D7) -> 0 | F7: =$C7*$H$2 -> 26400 | G7: =$D7*$H$3 -> 1050 | H7: =SUM($F7,$G7) -> 27450
A8: AUGUST | B8: =SUM('AUGUST 2026'!$H$1:$H$1000) -> 0 | C8: =COUNTIF('AUGUST 2026'!$G$1:$G$1000, "L") -> 0 | D8: =COUNTIF('AUGUST 2026'!$G$1:$G$1000, "B") -> 0 | E8: =B8-(C8+D8) -> 0 | F8: =$C8*$H$2 -> 0 | G8: =$D8*$H$3 -> 0 | H8: =SUM($F8,$G8) -> 0
A9: SEPTEMBER | B9: =SUM('SEPTEMBER 2026'!$H$1:$H$1000) -> 0 | C9: =COUNTIF('SEPTEMBER 2026'!$G$1:$G$1000, "L") -> 0 | D9: =COUNTIF('SEPTEMBER 2026'!$G$1:$G$1000, "B") -> 0 | E9: =B9-(C9+D9) -> 0 | F9: =$C9*$H$2 -> 0 | G9: =$D9*$H$3 -> 0 | H9: =SUM($F9,$G9) -> 0
A10: OCTOBER | B10: =SUM('OCTOBER 2026'!$H$1:$H$1000) -> 0 | C10: =COUNTIF('OCTOBER 2026'!$G$1:$G$1000, "L") -> 0 | D10: =COUNTIF('OCTOBER 2026'!$G$1:$G$1000, "B") -> 0 | E10: =B10-(C10+D10) -> 0 | F10: =$C10*$H$2 -> 0 | G10: =$D10*$H$3 -> 0 | H10: =SUM($F10,$G10) -> 0
A11: NOVEMBER | B11: =SUM('NOVEMBER 2026'!$H$1:$H$1000) -> 0 | C11: =COUNTIF('NOVEMBER 2026'!$G$1:$G$1000, "L") -> 0 | D11: =COUNTIF('NOVEMBER 2026'!$G$1:$G$1000, "B") -> 0 | E11: =B11-(C11+D11) -> 0 | F11: =$C11*$H$2 -> 0 | G11: =$D11*$H$3 -> 0 | H11: =SUM($F11,$G11) -> 0
A12: DECEMBER | B12: =SUM('DECEMBER 2026'!$H$1:$H$1000) -> 0 | C12: =COUNTIF('DECEMBER 2026'!$G$1:$G$1000, "L") -> 0 | D12: =COUNTIF('DECEMBER 2026'!$G$1:$G$1000, "B") -> 0 | E12: =B12-(C12+D12) -> 0 | F12: =$C12*$H$2 -> 0 | G12: =$D12*$H$3 -> 0 | H12: =SUM($F12,$G12) -> 0
A13: JANUARY | B13: =SUM('JANUARY 2027'!$H$1:$H$1000) -> 0 | C13: =COUNTIF('JANUARY 2027'!$G$1:$G$1000, "L") -> 0 | D13: =COUNTIF('JANUARY 2027'!$G$1:$G$1000, "B") -> 0 | E13: =B13-(C13+D13) -> 0 | F13: =$C13*$H$2 -> 0 | G13: =$D13*$H$3 -> 0 | H13: =SUM($F13,$G13) -> 0
A14: FEBRUARY | B14: =SUM('FEBRUARY 2027'!$H$1:$H$1000) -> 0 | C14: =COUNTIF('FEBRUARY 2027'!$G$1:$G$1000, "L") -> 0 | D14: =COUNTIF('FEBRUARY 2027'!$G$1:$G$1000, "B") -> 0 | E14: =B14-(C14+D14) -> 0 | F14: =$C14*$H$2 -> 0 | G14: =$D14*$H$3 -> 0 | H14: =SUM($F14,$G14) -> 0
A15: MARCH | B15: =SUM('MARCH 2027'!$H$1:$H$1000) -> 0 | C15: =COUNTIF('MARCH 2027'!$G$1:$G$1000, "L") -> 0 | D15: =COUNTIF('MARCH 2027'!$G$1:$G$1000, "B") -> 0 | E15: =B15-(C15+D15) -> 0 | F15: =$C15*$H$2 -> 0 | G15: =$D15*$H$3 -> 0 | H15: =SUM($F15,$G15) -> 0
A17: TOTAL | B17: =SUM(B6:B15) -> 227 | C17: =SUM(C6:C15) -> 224 | D17: =SUM(D6:D15) -> 3 | E17: =SUM(E6:E15) -> 0 | F17: =SUM(F6:F15) -> 179200 | G17: =SUM(G6:G15) -> 3150 | H17: =SUM(H6:H15) -> 182350

Sheet INVOICE CALCULATOR
A2: SL. NO. | B2: NAME | C2: QUANTITY | D2: PRICE | E2: TOTAL | H2: TAXABLE | I2: =SUM(E3:E18)-E23 -> 0
A4: 1 | E4: =C4*D4 -> 0 | H4: CGST @ 2.5% | I4: =I2*2.5% -> 0
A5: 2 | E5: =C5*D5 -> 0 | H5: SGST @ 2.5% | I5: =I4 -> 0
A6: 3 | E6: =C6*D6 -> 0
A7: 4 | E7: =C7*D7 -> 0 | H7: IGST @ 5% | I7: =I2*5% -> 0
A8: 5 | E8: =C8*D8 -> 0
A9: 6 | E9: =C9*D9 -> 0 | H9: ROUND OFF | I9: =ROUND((I2+I4+I5), 0)-(I2+I4+I5) -> 0
A10: 7 | E10: =C10*D10 -> 0
A11: 8 | E11: =C11*D11 -> 0 | H11: FINAL AMOUNT | I11: =I2+I4+I5+I9 -> 0
A12: 9 | E12: =C12*D12 -> 0
A13: 10 | E13: =C13*D13 -> 0
A14: 11 | E14: =C14*D14 -> 0
A15: 12 | E15: =C15*D15 -> 0
A16: 13 | E16: =C16*D16 -> 0
A17: 14 | E17: =C17*D17 -> 0
A18: 15 | E18: =C18*D18 -> 0
B21: TOTAL | C21: =SUM(C4:C18) -> 0 | E21: =SUM(E4:E18) -> 0
B23: LESS | E23: =E21*D23% -> 0
B25: TAXABLE | E25: =ROUND(D25/1.05, 0) -> 0

Sheet JUNE 2026
A1: SEEMA SAREE CENTRE
A2: SHREE GANPATI LOGISTIC AND TRANSPORT
A3: BILTY SUMMARY
A4: DATE OF RECEIVING | B4: TRANSPORT BILL NO. | C4: TRANSPORT NAME | D4: LR NO. | E4: PM. NO | F4: COMPANY | G4: TYPE (LOOSE / BOX) | H4: LOT | I4: TOTAL PARCEL | J4: ENTRY IN TALLY | K4: DATE OF OPENING | L4: DIRECT SALE FROM TRANSPORT | M4: DIRECT SALE NOT FROM TRANSPORT | N4: CHECKED FROM TRANSPORT
A6: 46174 | B6: 2863 | C6: SHREE GANPATI LOGISTIC AND TRANSPORT | D6: 184677 | E6: 7718 | F6: KAPIL | G6: L | H6: 1 | J6: YES
D7: 184679 | E7: 7723 | F7: KAPIL | G7: L | H7: 1 | J7: YES
D8: 184780 | E8: 7797 | F8: KAPIL | G8: L | H8: 1 | J8: YES
D9: 184990 | E9: 7861 | F9: KAPIL | G9: L | H9: 1 | J9: YES
D10: 184608 | E10: 465 | F10: RAMDEV FASHION | G10: L | H10: 1 | J10: YES
D11: 184825 | E11: 455 | F11: DAMINI | G11: L | H11: 1 | J11: YES
D12: 184826 | E12: 456 | F12: DAMINI | G12: L | H12: 1 | J12: YES
D13: 184641 | E13: 459 | F13: RAMDEV FASHION | G13: L | H13: 1 | I13: TOTAL 8 PARCEL | J13: YES
A15: 46174 | B15: 18367 | C15: SHREE GANPATI LOGISTIC AND TRANSPORT | D15: 184859 | E15: 1378 | F15: SUCHITRA SILK MILLS | G15: L | H15: 1 | J15: YES
D16: 183555 | E16: 2711 | F16: CHARANJEET | G16: L | H16: 1 | I16: TOTAL 2 PARCEL | J16: YES
A18: 46175 | B18: 2866 | C18: SHREE GANPATI LOGISTIC AND TRANSPORT | D18: 184680 | E18: 7714 | F18: KAPIL | G18: L | H18: 1 | J18: YES
D19: 184676 | E19: 7713 | F19: KAPIL | G19: L | H19: 1 | J19: YES
D20: 184678 | E20: 7722 | F20: KAPIL | G20: L | H20: 1 | J20: YES
D21: 184779 | E21: 7799 | F21: KAPIL | G21: L | H21: 1 | J21: YES
D22: 184941 | E22: 171 | F22: SHREE LAXMI DEVI FASHION | G22: L | H22: 1 | J22: YES
D23: 184947 | E23: 177 | F23: SHREE LAXMI DEVI FASHION | G23: L | H23: 1 | J23: YES
D24: 184946 | E24: 176 | F24: SHREE LAXMI DEVI FASHION | G24: L | H24: 1 | J24: YES
D25: 184942 | E25: 172 | F25: SHREE LAXMI DEVI FASHION | G25: L | H25: 1 | I25: TOTAL 8 PARCEL | J25: YES
A27: 46175 | B27: 2757 | C27: SHREE GANPATI LOGISTIC AND TRANSPORT | D27: 184264 | E27: 128 | F27: MATRACHAYA | G27: L | H27: 1 | J27: YES
D28: 184263 | E28: 129 | F28: MATRACHAYA | G28: L | H28: 1 | I28: TOTAL 2 PARCEL | J28: YES
A30: 46176 | B30: 2759 | C30: SHREE GANPATI LOGISTIC AND TRANSPORT | D30: 177853 | E30: 52567 | F30: KAPIL | G30: L | H30: 1 | J30: YES
D31: 181680 | E31: 762 | F31: GURUWANI | G31: L | H31: 1 | J31: YES
D32: 184947 | E32: 179 | F32: SHREE LAXMI DEVI FASHION | G32: L | H32: 1 | J32: YES
D33: 184948 | E33: 178 | F33: SHREE LAXMI DEVI FASHION | G33: L | H33: 1 | J33: YES
D34: 184943 | E34: 173 | F34: SHREE LAXMI DEVI FASHION | G34: L | H34: 1 | I34: TOTAL 5 PARCEL | J34: YES
A36: 46181 | B36: 2724 | C36: SHREE GANPATI LOGISTIC AND TRANSPORT | D36: 185163 | E36: 475 | F36: RAMDEV FASHION | G36: L | H36: 1 | J36: YES
D37: 185349 | E37: 296 | F37: KAMLAPATI SAREE | G37: L | H37: 1 | J37: YES
D38: 185166 | E38: 483 | F38: RAMDEV FASHION | G38: L | H38: 1 | J38: YES
D39: 185344 | E39: 491 | F39: RAMDEV FASHION | G39: L | H39: 1 | J39: YES
D40: 185066 | E40: 469 | F40: RAMDEV FASHION | G40: L | H40: 1 | J40: YES
D41: 185164 | E41: 476 | F41: RAMDEV FASHION | G41: L | H41: 1 | J41: YES
D42: 185100 | E42: 281 | F42: KAMLAPATI | G42: L | H42: 1 | J42: YES
D43: 184786 | E43: 875 | F43: DEV SHREE | G43: L | H43: 1 | I43: TOTAL 8 PARCEL | J43: YES
A45: 46181 | B45: 18414 | C45: SHREE GANPATI LOGISTIC AND TRANSPORT | D45: 185346 | E45: 493 | F45: RAMDEV FASHION | G45: L | H45: 1 | J45: YES
D46: 184827 | E46: 457 | F46: DAMINI | G46: L | H46: 1 | J46: YES
D47: 185162 | E47: 474 | F47: RAMDEV FASHION | G47: L | H47: 1 | J47: YES
...

Sheet JULY 2026
A1: SEEMA SAREE CENTRE
A2: SHREE GANPATI LOGISTIC AND TRANSPORT
A3: BILTY SUMMARY
A4: DATE OF RECEIVING | B4: TRANSPORT BILL NO. | C4: TRANSPORT NAME | D4: LR NO. | E4: PM. NO | F4: COMPANY | G4: TYPE (LOOSE / BOX) | H4: LOT | I4: TOTAL PARCEL | J4: ENTRY IN TALLY | K4: DATE OF OPENING | L4: DIRECT SALE FROM TRANSPORT | M4: DIRECT SALE NOT FROM TRANSPORT | N4: CHECKED FROM TRANSPORT
A6: 46204 | B6: 2891 | C6: SHREE GANPATI LOGISTIC AND TRANSPORT | D6: 187223 | E6: 9527 | F6: KAPIL | G6: L | H6: 1 | J6: YES
D7: 186575 | E7: 8951 | F7: KAPIL | G7: L | H7: 1 | J7: YES
D8: 187221 | E8: 9533 | F8: KAPIL | G8: L | H8: 1 | J8: YES
D9: 187222 | E9: 9528 | F9: KAPIL | G9: L | H9: 1 | J9: YES
D10: 186577 | E10: 8928 | F10: KAPIL | G10: L | H10: 1 | J10: YES
D11: 187171 | E11: 9487 | F11: KAPIL | G11: L | H11: 1 | J11: YES
D12: 187170 | E12: 9445 | F12: KAPIL | G12: L | H12: 1 | I12: TOTAL 7 PARCEL | J12: YES
A14: 46205 | B14: 18748 | C14: SHREE GANPATI LOGISTIC AND TRANSPORT | D14: 185699 | E14: 2983 | F14: SHRIWALI | G14: B | H14: 1 | J14: YES | K14: 46205 | L14: BHOLA BHAGAT STORE - TARAPUR
D15: 187127 | E15: 544 | F15: RAMDEV FASHION | G15: L | H15: 1 | J15: NO
D16: 187498 | E16: 9135 | F16: AMBEY | G16: L | H16: 1 | J16: YES
D17: 187486 | E17: 87 | F17: W/L | G17: L | H17: 1 | J17: NO
D18: 187494 | E18: 9187 | F18: AMBEY | G18: L | H18: 1 | J18: YES
D19: 187484 | E19: 90 | F19: W/L | G19: L | H19: 1 | I19: TOTAL 6 PARCEL | J19: NO
A21: 46210 | B21: 18767 | C21: SHREE GANPATI LOGISTIC AND TRANSPORT | D21: 187740 | E21: 10052 | F21: KAPIL | G21: L | H21: 1 | J21: NO
D22: 187622 | E22: 9922 | F22: KAPIL | G22: L | H22: 1 | J22: NO
D23: 187329 | E23: 9567 | F23: KAPIL | G23: L | H23: 1 | J23: NO
D24: 183979 | E24: 7094 | F24: AMBEY | G24: L | H24: 1 | J24: NO
D25: 183978 | E25: 7643 | F25: AMBEY | G25: L | H25: 1 | J25: NO
D26: 187495 | E26: 9178 | F26: AMBEY | G26: L | H26: 1 | I26: TOTAL 6 PARCEL | J26: NO
A28: 46210 | B28: 18772 | C28: SHREE GANPATI LOGISTIC AND TRANSPORT | D28: 175961 | E28: 15 | F28: KARIGAR | G28: L | H28: 1 | J28: NO
D29: 187076 | E29: 2475 | F29: TANU | G29: L | H29: 1 | J29: NO
D30: 187078 | E30: 2473 | F30: TANU | G30: L | H30: 1 | J30: NO
D31: 186866 | E31: 2413 | F31: TANU | G31: L | H31: 1 | J31: NO
D32: 187061 | E32: 233 | F32: MATRACHAYA | G32: L | H32: 1 | J32: NO
D33: 187064 | E33: 236 | F33: MATRACHAYA | G33: L | H33: 1 | J33: NO
D34: 187638 | E34: 274 | F34: MATRACHAYA | G34: L | H34: 1 | J34: NO
D35: 187077 | E35: 2474 | F35: TANU | G35: L | H35: 1 | J35: NO
D36: 187641 | E36: 268 | F36: MATRACHAYA | G36: L | H36: 1 | I36: TOTAL 9 PARCEL | J36: NO
A38: 46212 | B38: 2914 | C38: SHREE GANPATI LOGISTIC AND TRANSPORT | D38: 188138 | E38: 10305 | F38: KAPIL | G38: L | H38: 1 | J38: NO
D39: 187952 | E39: 530 | F39: DAMINI | G39: L | H39: 1 | J39: NO
D40: 188139 | E40: 10332 | F40: KAPIL | G40: L | H40: 1 | J40: NO
D41: 188038 | E41: 10248 | F41: KAPIL | G41: L | H41: 1 | J41: NO
D42: 187957 | E42: 529 | F42: DAMINI | G42: L | H42: 1 | J42: NO
D43: 187950 | E43: 531 | F43: DAMINI | G43: L | H43: 1 | I43: TOTAL 6 PARCEL | J43: NO

Sheet AUGUST 2026
A1: SEEMA SAREE CENTRE
A2: SHREE GANPATI LOGISTIC AND TRANSPORT
A3: BILTY SUMMARY
A4: DATE OF RECEIVING | B4: TRANSPORT BILL NO. | C4: TRANSPORT NAME | D4: LR NO. | E4: PM. NO | F4: COMPANY | G4: TYPE (LOOSE / BOX) | H4: LOT | I4: TOTAL PARCEL | J4: ENTRY IN TALLY | K4: DATE OF OPENING | L4: DIRECT SALE FROM TRANSPORT | M4: DIRECT SALE NOT FROM TRANSPORT | N4: CHECKED FROM TRANSPORT

Sheet SEPTEMBER 2026
A1: SEEMA SAREE CENTRE
A2: SHREE GANPATI LOGISTIC AND TRANSPORT
A3: BILTY SUMMARY
A4: DATE OF RECEIVING | B4: TRANSPORT BILL NO. | C4: TRANSPORT NAME | D4: LR NO. | E4: PM. NO | F4: COMPANY | G4: TYPE (LOOSE / BOX) | H4: LOT | I4: TOTAL PARCEL | J4: ENTRY IN TALLY | K4: DATE OF OPENING | L4: DIRECT SALE FROM TRANSPORT | M4: DIRECT SALE NOT FROM TRANSPORT | N4: CHECKED FROM TRANSPORT

Sheet OCTOBER 2026
A1: SEEMA SAREE CENTRE
A2: SHREE GANPATI LOGISTIC AND TRANSPORT
A3: BILTY SUMMARY
A4: DATE OF RECEIVING | B4: TRANSPORT BILL NO. | C4: TRANSPORT NAME | D4: LR NO. | E4: PM. NO | F4: COMPANY | G4: TYPE (LOOSE / BOX) | H4: LOT | I4: TOTAL PARCEL | J4: ENTRY IN TALLY | K4: DATE OF OPENING | L4: DIRECT SALE FROM TRANSPORT | M4: DIRECT SALE NOT FROM TRANSPORT | N4: CHECKED FROM TRANSPORT

Sheet NOVEMBER 2026
A1: SEEMA SAREE CENTRE
A2: SHREE GANPATI LOGISTIC AND TRANSPORT
A3: BILTY SUMMARY
A4: DATE OF RECEIVING | B4: TRANSPORT BILL NO. | C4: TRANSPORT NAME | D4: LR NO. | E4: PM. NO | F4: COMPANY | G4: TYPE (LOOSE / BOX) | H4: LOT | I4: TOTAL PARCEL | J4: ENTRY IN TALLY | K4: DATE OF OPENING | L4: DIRECT SALE FROM TRANSPORT | M4: DIRECT SALE NOT FROM TRANSPORT | N4: CHECKED FROM TRANSPORT

Sheet DECEMBER 2026
A1: SEEMA SAREE CENTRE
A2: SHREE GANPATI LOGISTIC AND TRANSPORT
A3: BILTY SUMMARY
A4: DATE OF RECEIVING | B4: TRANSPORT BILL NO. | C4: TRANSPORT NAME | D4: LR NO. | E4: PM. NO | F4: COMPANY | G4: TYPE (LOOSE / BOX) | H4: LOT | I4: TOTAL PARCEL | J4: ENTRY IN TALLY | K4: DATE OF OPENING | L4: DIRECT SALE FROM TRANSPORT | M4: DIRECT SALE NOT FROM TRANSPORT | N4: CHECKED FROM TRANSPORT

Sheet JANUARY 2027
A1: SEEMA SAREE CENTRE
A2: SHREE GANPATI LOGISTIC AND TRANSPORT
A3: BILTY SUMMARY
A4: DATE OF RECEIVING | B4: TRANSPORT BILL NO. | C4: TRANSPORT NAME | D4: LR NO. | E4: PM. NO | F4: COMPANY | G4: TYPE (LOOSE / BOX) | H4: LOT | I4: TOTAL PARCEL | J4: ENTRY IN TALLY | K4: DATE OF OPENING | L4: DIRECT SALE FROM TRANSPORT | M4: DIRECT SALE NOT FROM TRANSPORT | N4: CHECKED FROM TRANSPORT

Sheet FEBRUARY 2027
A1: SEEMA SAREE CENTRE
A2: SHREE GANPATI LOGISTIC AND TRANSPORT
A3: BILTY SUMMARY
A4: DATE OF RECEIVING | B4: TRANSPORT BILL NO. | C4: TRANSPORT NAME | D4: LR NO. | E4: PM. NO | F4: COMPANY | G4: TYPE (LOOSE / BOX) | H4: LOT | I4: TOTAL PARCEL | J4: ENTRY IN TALLY | K4: DATE OF OPENING | L4: DIRECT SALE FROM TRANSPORT | M4: DIRECT SALE NOT FROM TRANSPORT | N4: CHECKED FROM TRANSPORT

Sheet MARCH 2027
A1: SEEMA SAREE CENTRE
A2: SHREE GANPATI LOGISTIC AND TRANSPORT
A3: BILTY SUMMARY
A4: DATE OF RECEIVING | B4: TRANSPORT BILL NO. | C4: TRANSPORT NAME | D4: LR NO. | E4: PM. NO | F4: COMPANY | G4: TYPE (LOOSE / BOX) | H4: LOT | I4: TOTAL PARCEL | J4: ENTRY IN TALLY | K4: DATE OF OPENING | L4: DIRECT SALE FROM TRANSPORT | M4: DIRECT SALE NOT FROM TRANSPORT | N4: CHECKED FROM TRANSPORT
